Workbook

Sheet Gap Sheet
A1: Chennai
A3: Skills | B3: Line Up | C3: Slot Metrics | K3: Panel Metrics
C4: R1 Slots | G4: R2 Slots | K4: R1 Panel | O4: R2 Panel
C5: Ask | D5: Available | E5: Gap | F5: Excess | G5: Ask | H5: Available | I5: Gap | J5: Excess | K5: Ask | L5: Available | M5: Gap | N5: Excess | O5: Ask | P5: Available | Q5: Gap | R5: Excess
A6: Databricks | B6: 50 | C6: 50 | D6: =SUMPRODUCT((TRIM('Panel Details'!$E$2:$E$501)=TRIM($A6))*('Panel Details'!$I$2:$I$501="R1")*N('Panel Details'!$J$2:$J$501)) -> 0 | E6: =IF(($C6-$D6)<0,0,$C6-$D6) -> 50 | F6: =IF($E6=0,$D6-$C6,0) -> 0 | G6: 20 | H6: =SUMPRODUCT((TRIM('Panel Details'!$E$2:$E$501)=TRIM($A6))*('Panel Details'!$I$2:$I$501="R2")*N('Panel Details'!$J$2:$J$501)) -> 0 | I6: =IF(($G6-$H6)<0,0,$G6-$H6) -> 20 | J6: =IF($I6=0,$H6-$G6,0) -> 0 | K6: =_xlfn.CEILING.MATH($C6/8) -> 7 | L6: =_xlfn.CEILING.MATH($D6/8) -> 0 | M6: =IF(($K6-$L6)<0,0,$K6-$L6) -> 7 | N6: =IF($M6=0,$L6-$K6,0) -> 0 | O6: =_xlfn.CEILING.MATH($G6/8) -> 3 | P6: =_xlfn.CEILING.MATH($H6/8) -> 0 | Q6: =IF(($O6-$P6)<0,0,$O6-$P6) -> 3 | R6: =IF($Q6=0,$P6-$O6,0) -> 0
A7: Gen AI | B7: 50 | C7: 50 | D7: =SUMPRODUCT((TRIM('Panel Details'!$E$2:$E$501)=TRIM($A7))*('Panel Details'!$I$2:$I$501="R1")*N('Panel Details'!$J$2:$J$501)) -> 0 | E7: =IF(($C7-$D7)<0,0,$C7-$D7) -> 50 | F7: =IF($E7=0,$D7-$C7,0) -> 0 | G7: 20 | H7: =SUMPRODUCT((TRIM('Panel Details'!$E$2:$E$501)=TRIM($A7))*('Panel Details'!$I$2:$I$501="R2")*N('Panel Details'!$J$2:$J$501)) -> 0 | I7: =IF(($G7-$H7)<0,0,$G7-$H7) -> 20 | J7: =IF($I7=0,$H7-$G7,0) -> 0 | K7: =_xlfn.CEILING.MATH($C7/8) -> 7 | L7: =_xlfn.CEILING.MATH($D7/8) -> 0 | M7: =IF(($K7-$L7)<0,0,$K7-$L7) -> 7 | N7: =IF($M7=0,$L7-$K7,0) -> 0 | O7: =_xlfn.CEILING.MATH($G7/8) -> 3 | P7: =_xlfn.CEILING.MATH($H7/8) -> 0 | Q7: =IF(($O7-$P7)<0,0,$O7-$P7) -> 3 | R7: =IF($Q7=0,$P7-$O7,0) -> 0
A8: GCP Data Engineering | B8: 50 | C8: 50 | D8: =SUMPRODUCT((TRIM('Panel Details'!$E$2:$E$501)=TRIM($A8))*('Panel Details'!$I$2:$I$501="R1")*N('Panel Details'!$J$2:$J$501)) -> 0 | E8: =IF(($C8-$D8)<0,0,$C8-$D8) -> 50 | F8: =IF($E8=0,$D8-$C8,0) -> 0 | G8: 20 | H8: =SUMPRODUCT((TRIM('Panel Details'!$E$2:$E$501)=TRIM($A8))*('Panel Details'!$I$2:$I$501="R2")*N('Panel Details'!$J$2:$J$501)) -> 0 | I8: =IF(($G8-$H8)<0,0,$G8-$H8) -> 20 | J8: =IF($I8=0,$H8-$G8,0) -> 0 | K8: =_xlfn.CEILING.MATH($C8/8) -> 7 | L8: =_xlfn.CEILING.MATH($D8/8) -> 0 | M8: =IF(($K8-$L8)<0,0,$K8-$L8) -> 7 | N8: =IF($M8=0,$L8-$K8,0) -> 0 | O8: =_xlfn.CEILING.MATH($G8/8) -> 3 | P8: =_xlfn.CEILING.MATH($H8/8) -> 0 | Q8: =IF(($O8-$P8)<0,0,$O8-$P8) -> 3 | R8: =IF($Q8=0,$P8-$O8,0) -> 0
A9: Pyspark | B9: 30 | C9: 30 | D9: =SUMPRODUCT((TRIM('Panel Details'!$E$2:$E$501)=TRIM($A9))*('Panel Details'!$I$2:$I$501="R1")*N('Panel Details'!$J$2:$J$501)) -> 0 | E9: =IF(($C9-$D9)<0,0,$C9-$D9) -> 30 | F9: =IF($E9=0,$D9-$C9,0) -> 0 | G9: 12 | H9: =SUMPRODUCT((TRIM('Panel Details'!$E$2:$E$501)=TRIM($A9))*('Panel Details'!$I$2:$I$501="R2")*N('Panel Details'!$J$2:$J$501)) -> 0 | I9: =IF(($G9-$H9)<0,0,$G9-$H9) -> 12 | J9: =IF($I9=0,$H9-$G9,0) -> 0 | K9: =_xlfn.CEILING.MATH($C9/8) -> 4 | L9: =_xlfn.CEILING.MATH($D9/8) -> 0 | M9: =IF(($K9-$L9)<0,0,$K9-$L9) -> 4 | N9: =IF($M9=0,$L9-$K9,0) -> 0 | O9: =_xlfn.CEILING.MATH($G9/8) -> 2 | P9: =_xlfn.CEILING.MATH($H9/8) -> 0 | Q9: =IF(($O9-$P9)<0,0,$O9-$P9) -> 2 | R9: =IF($Q9=0,$P9-$O9,0) -> 0
A10: Machine learning | B10: 30 | C10: 30 | D10: =SUMPRODUCT((TRIM('Panel Details'!$E$2:$E$501)=TRIM($A10))*('Panel Details'!$I$2:$I$501="R1")*N('Panel Details'!$J$2:$J$501)) -> 0 | E10: =IF(($C10-$D10)<0,0,$C10-$D10) -> 30 | F10: =IF($E10=0,$D10-$C10,0) -> 0 | G10: 12 | H10: =SUMPRODUCT((TRIM('Panel Details'!$E$2:$E$501)=TRIM($A10))*('Panel Details'!$I$2:$I$501="R2")*N('Panel Details'!$J$2:$J$501)) -> 0 | I10: =IF(($G10-$H10)<0,0,$G10-$H10) -> 12 | J10: =IF($I10=0,$H10-$G10,0) -> 0 | K10: =_xlfn.CEILING.MATH($C10/8) -> 4 | L10: =_xlfn.CEILING.MATH($D10/8) -> 0 | M10: =IF(($K10-$L10)<0,0,$K10-$L10) -> 4 | N10: =IF($M10=0,$L10-$K10,0) -> 0 | O10: =_xlfn.CEILING.MATH($G10/8) -> 2 | P10: =_xlfn.CEILING.MATH($H10/8) -> 0 | Q10: =IF(($O10-$P10)<0,0,$O10-$P10) -> 2 | R10: =IF($Q10=0,$P10-$O10,0) -> 0
A11: Azure Data Engineering | B11: 40 | C11: 40 | D11: =SUMPRODUCT((TRIM('Panel Details'!$E$2:$E$501)=TRIM($A11))*('Panel Details'!$I$2:$I$501="R1")*N('Panel Details'!$J$2:$J$501)) -> 0 | E11: =IF(($C11-$D11)<0,0,$C11-$D11) -> 40 | F11: =IF($E11=0,$D11-$C11,0) -> 0 | G11: 16 | H11: =SUMPRODUCT((TRIM('Panel Details'!$E$2:$E$501)=TRIM($A11))*('Panel Details'!$I$2:$I$501="R2")*N('Panel Details'!$J$2:$J$501)) -> 0 | I11: =IF(($G11-$H11)<0,0,$G11-$H11) -> 16 | J11: =IF($I11=0,$H11-$G11,0) -> 0 | K11: =_xlfn.CEILING.MATH($C11/8) -> 5 | L11: =_xlfn.CEILING.MATH($D11/8) -> 0 | M11: =IF(($K11-$L11)<0,0,$K11-$L11) -> 5 | N11: =IF($M11=0,$L11-$K11,0) -> 0 | O11: =_xlfn.CEILING.MATH($G11/8) -> 2 | P11: =_xlfn.CEILING.MATH($H11/8) -> 0 | Q11: =IF(($O11-$P11)<0,0,$O11-$P11) -> 2 | R11: =IF($Q11=0,$P11-$O11,0) -> 0
A12: Total | B12: =SUM(B6:B11) -> 250 | C12: =SUM(C6:C11) -> 250 | D12: =SUM(D6:D11) -> 0 | E12: =SUM(E6:E11) -> 250 | F12: =SUM(F6:F11) -> 0 | G12: =SUM(G6:G11) -> 100 | H12: =SUM(H6:H11) -> 0 | I12: =SUM(I6:I11) -> 100 | ... R12: =SUM(R6:R11) -> 0

Sheet Pivot
B3: Sum of Number of Slots
B4: Skills | C4: R1 | D4: R2 | E4: Grand Total
B5: Databricks | C5: =SUMPRODUCT((TRIM('Panel Details'!$E$2:$E$501)=TRIM($B5))*('Panel Details'!$I$2:$I$501="R1")*N('Panel Details'!$J$2:$J$501)) -> 0 | D5: =SUMPRODUCT((TRIM('Panel Details'!$E$2:$E$501)=TRIM($B5))*('Panel Details'!$I$2:$I$501="R2")*N('Panel Details'!$J$2:$J$501)) -> 0 | E5: =C5+D5 -> 0
B6: Gen AI | C6: =SUMPRODUCT((TRIM('Panel Details'!$E$2:$E$501)=TRIM($B6))*('Panel Details'!$I$2:$I$501="R1")*N('Panel Details'!$J$2:$J$501)) -> 0 | D6: =SUMPRODUCT((TRIM('Panel Details'!$E$2:$E$501)=TRIM($B6))*('Panel Details'!$I$2:$I$501="R2")*N('Panel Details'!$J$2:$J$501)) -> 0 | E6: =C6+D6 -> 0
B7: GCP Data Engineering | C7: =SUMPRODUCT((TRIM('Panel Details'!$E$2:$E$501)=TRIM($B7))*('Panel Details'!$I$2:$I$501="R1")*N('Panel Details'!$J$2:$J$501)) -> 0 | D7: =SUMPRODUCT((TRIM('Panel Details'!$E$2:$E$501)=TRIM($B7))*('Panel Details'!$I$2:$I$501="R2")*N('Panel Details'!$J$2:$J$501)) -> 0 | E7: =C7+D7 -> 0
B8: Pyspark | C8: =SUMPRODUCT((TRIM('Panel Details'!$E$2:$E$501)=TRIM($B8))*('Panel Details'!$I$2:$I$501="R1")*N('Panel Details'!$J$2:$J$501)) -> 0 | D8: =SUMPRODUCT((TRIM('Panel Details'!$E$2:$E$501)=TRIM($B8))*('Panel Details'!$I$2:$I$501="R2")*N('Panel Details'!$J$2:$J$501)) -> 0 | E8: =C8+D8 -> 0
B9: Machine learning | C9: =SUMPRODUCT((TRIM('Panel Details'!$E$2:$E$501)=TRIM($B9))*('Panel Details'!$I$2:$I$501="R1")*N('Panel Details'!$J$2:$J$501)) -> 0 | D9: =SUMPRODUCT((TRIM('Panel Details'!$E$2:$E$501)=TRIM($B9))*('Panel Details'!$I$2:$I$501="R2")*N('Panel Details'!$J$2:$J$501)) -> 0 | E9: =C9+D9 -> 0
B10: Azure Data Engineering | C10: =SUMPRODUCT((TRIM('Panel Details'!$E$2:$E$501)=TRIM($B10))*('Panel Details'!$I$2:$I$501="R1")*N('Panel Details'!$J$2:$J$501)) -> 0 | D10: =SUMPRODUCT((TRIM('Panel Details'!$E$2:$E$501)=TRIM($B10))*('Panel Details'!$I$2:$I$501="R2")*N('Panel Details'!$J$2:$J$501)) -> 0 | E10: =C10+D10 -> 0
B11: Grand Total | C11: =SUM(C5:C10) -> 0 | D11: =SUM(D5:D10) -> 0 | E11: =SUM(E5:E10) -> 0

Sheet Skill Mapping
A1: Survey/Gap Skill | B1: Master Skill
A2: Databricks | B2: Databricks - Data Engineer
A3: Gen AI | B3: Gen AI
A4: GCP Data Engineering | B4: Google Cloud Platform (GCP) - Data Engineer
A5: Pyspark | B5: Pyspark
A6: Machine learning | B6: Machine Learning
A7: Azure Data Engineering | B7: Microsoft Azure - Data Engineer

Sheet Panel Details
A1: ID | B1: Email | C1: Name | D1: Mobile | E1: Primary Skill | F1: Secondary Skill | G1: Location | H1: Designation | I1: Level | J1: Number of Slots | K1: Comments | L1: In Master Panel List? | M1: Panel to Travel | O1: srcRow
A2: =IF($O2="","",INDEX('Auto Process'!$AC:$AC,$O2)) | B2: =IF($O2="","",INDEX('Auto Process'!$AD:$AD,$O2)) | C2: =IF($O2="","",INDEX('Auto Process'!$AE:$AE,$O2)) | D2: =IF($O2="","",INDEX('Auto Process'!$AF:$AF,$O2)) | E2: =IF($O2="","",INDEX('Auto Process'!$AG:$AG,$O2)) | F2: =IF($O2="","",INDEX('Auto Process'!$AH:$AH,$O2)) | G2: =IF($O2="","",INDEX('Auto Process'!$AI:$AI,$O2)) | H2: =IF($O2="","",INDEX('Auto Process'!$AJ:$AJ,$O2)) | I2: =IF($O2="","",INDEX('Auto Process'!$AK:$AK,$O2)) | J2: =IF($O2="","",INDEX('Auto Process'!$AL:$AL,$O2)) | K2: =IF($O2="","",INDEX('Auto Process'!$AM:$AM,$O2)) | L2: =IF($O2="","",INDEX('Auto Process'!$AN:$AN,$O2)) | M2: =IF($O2="","",INDEX('Auto Process'!$AO:$AO,$O2)) | O2: =IFERROR(_xlfn.AGGREGATE(15,6,ROW('Auto Process'!$D$4:$D$503)/('Auto Process'!$D$4:$D$503="Panel Details"),ROW()-1),"")
A3: =IF($O3="","",INDEX('Auto Process'!$AC:$AC,$O3)) | B3: =IF($O3="","",INDEX('Auto Process'!$AD:$AD,$O3)) | C3: =IF($O3="","",INDEX('Auto Process'!$AE:$AE,$O3)) | D3: =IF($O3="","",INDEX('Auto Process'!$AF:$AF,$O3)) | E3: =IF($O3="","",INDEX('Auto Process'!$AG:$AG,$O3)) | F3: =IF($O3="","",INDEX('Auto Process'!$AH:$AH,$O3)) | G3: =IF($O3="","",INDEX('Auto Process'!$AI:$AI,$O3)) | H3: =IF($O3="","",INDEX('Auto Process'!$AJ:$AJ,$O3)) | I3: =IF($O3="","",INDEX('Auto Process'!$AK:$AK,$O3)) | J3: =IF($O3="","",INDEX('Auto Process'!$AL:$AL,$O3)) | K3: =IF($O3="","",INDEX('Auto Process'!$AM:$AM,$O3)) | L3: =IF($O3="","",INDEX('Auto Process'!$AN:$AN,$O3)) | M3: =IF($O3="","",INDEX('Auto Process'!$AO:$AO,$O3)) | O3: =IFERROR(_xlfn.AGGREGATE(15,6,ROW('Auto Process'!$D$4:$D$503)/('Auto Process'!$D$4:$D$503="Panel Details"),ROW()-1),"")
A4: =IF($O4="","",INDEX('Auto Process'!$AC:$AC,$O4)) | B4: =IF($O4="","",INDEX('Auto Process'!$AD:$AD,$O4)) | C4: =IF($O4="","",INDEX('Auto Process'!$AE:$AE,$O4)) | D4: =IF($O4="","",INDEX('Auto Process'!$AF:$AF,$O4)) | E4: =IF($O4="","",INDEX('Auto Process'!$AG:$AG,$O4)) | F4: =IF($O4="","",INDEX('Auto Process'!$AH:$AH,$O4)) | G4: =IF($O4="","",INDEX('Auto Process'!$AI:$AI,$O4)) | H4: =IF($O4="","",INDEX('Auto Process'!$AJ:$AJ,$O4)) | I4: =IF($O4="","",INDEX('Auto Process'!$AK:$AK,$O4)) | J4: =IF($O4="","",INDEX('Auto Process'!$AL:$AL,$O4)) | K4: =IF($O4="","",INDEX('Auto Process'!$AM:$AM,$O4)) | L4: =IF($O4="","",INDEX('Auto Process'!$AN:$AN,$O4)) | M4: =IF($O4="","",INDEX('Auto Process'!$AO:$AO,$O4)) | O4: =IFERROR(_xlfn.AGGREGATE(15,6,ROW('Auto Process'!$D$4:$D$503)/('Auto Process'!$D$4:$D$503="Panel Details"),ROW()-1),"")
A5: =IF($O5="","",INDEX('Auto Process'!$AC:$AC,$O5)) | B5: =IF($O5="","",INDEX('Auto Process'!$AD:$AD,$O5)) | C5: =IF($O5="","",INDEX('Auto Process'!$AE:$AE,$O5)) | D5: =IF($O5="","",INDEX('Auto Process'!$AF:$AF,$O5)) | E5: =IF($O5="","",INDEX('Auto Process'!$AG:$AG,$O5)) | F5: =IF($O5="","",INDEX('Auto Process'!$AH:$AH,$O5)) | G5: =IF($O5="","",INDEX('Auto Process'!$AI:$AI,$O5)) | H5: =IF($O5="","",INDEX('Auto Process'!$AJ:$AJ,$O5)) | I5: =IF($O5="","",INDEX('Auto Process'!$AK:$AK,$O5)) | J5: =IF($O5="","",INDEX('Auto Process'!$AL:$AL,$O5)) | K5: =IF($O5="","",INDEX('Auto Process'!$AM:$AM,$O5)) | L5: =IF($O5="","",INDEX('Auto Process'!$AN:$AN,$O5)) | M5: =IF($O5="","",INDEX('Auto Process'!$AO:$AO,$O5)) | O5: =IFERROR(_xlfn.AGGREGATE(15,6,ROW('Auto Process'!$D$4:$D$503)/('Auto Process'!$D$4:$D$503="Panel Details"),ROW()-1),"")
A6: =IF($O6="","",INDEX('Auto Process'!$AC:$AC,$O6)) | B6: =IF($O6="","",INDEX('Auto Process'!$AD:$AD,$O6)) | C6: =IF($O6="","",INDEX('Auto Process'!$AE:$AE,$O6)) | D6: =IF($O6="","",INDEX('Auto Process'!$AF:$AF,$O6)) | E6: =IF($O6="","",INDEX('Auto Process'!$AG:$AG,$O6)) | F6: =IF($O6="","",INDEX('Auto Process'!$AH:$AH,$O6)) | G6: =IF($O6="","",INDEX('Auto Process'!$AI:$AI,$O6)) | H6: =IF($O6="","",INDEX('Auto Process'!$AJ:$AJ,$O6)) | I6: =IF($O6="","",INDEX('Auto Process'!$AK:$AK,$O6)) | J6: =IF($O6="","",INDEX('Auto Process'!$AL:$AL,$O6)) | K6: =IF($O6="","",INDEX('Auto Process'!$AM:$AM,$O6)) | L6: =IF($O6="","",INDEX('Auto Process'!$AN:$AN,$O6)) | M6: =IF($O6="","",INDEX('Auto Process'!$AO:$AO,$O6)) | O6: =IFERROR(_xlfn.AGGREGATE(15,6,ROW('Auto Process'!$D$4:$D$503)/('Auto Process'!$D$4:$D$503="Panel Details"),ROW()-1),"")
A7: =IF($O7="","",INDEX('Auto Process'!$AC:$AC,$O7)) | B7: =IF($O7="","",INDEX('Auto Process'!$AD:$AD,$O7)) | C7: =IF($O7="","",INDEX('Auto Process'!$AE:$AE,$O7)) | D7: =IF($O7="","",INDEX('Auto Process'!$AF:$AF,$O7)) | E7: =IF($O7="","",INDEX('Auto Process'!$AG:$AG,$O7)) | F7: =IF($O7="","",INDEX('Auto Process'!$AH:$AH,$O7)) | G7: =IF($O7="","",INDEX('Auto Process'!$AI:$AI,$O7)) | H7: =IF($O7="","",INDEX('Auto Process'!$AJ:$AJ,$O7)) | I7: =IF($O7="","",INDEX('Auto Process'!$AK:$AK,$O7)) | J7: =IF($O7="","",INDEX('Auto Process'!$AL:$AL,$O7)) | K7: =IF($O7="","",INDEX('Auto Process'!$AM:$AM,$O7)) | L7: =IF($O7="","",INDEX('Auto Process'!$AN:$AN,$O7)) | M7: =IF($O7="","",INDEX('Auto Process'!$AO:$AO,$O7)) | O7: =IFERROR(_xlfn.AGGREGATE(15,6,ROW('Auto Process'!$D$4:$D$503)/('Auto Process'!$D$4:$D$503="Panel Details"),ROW()-1),"")
A8: =IF($O8="","",INDEX('Auto Process'!$AC:$AC,$O8)) | B8: =IF($O8="","",INDEX('Auto Process'!$AD:$AD,$O8)) | C8: =IF($O8="","",INDEX('Auto Process'!$AE:$AE,$O8)) | D8: =IF($O8="","",INDEX('Auto Process'!$AF:$AF,$O8)) | E8: =IF($O8="","",INDEX('Auto Process'!$AG:$AG,$O8)) | F8: =IF($O8="","",INDEX('Auto Process'!$AH:$AH,$O8)) | G8: =IF($O8="","",INDEX('Auto Process'!$AI:$AI,$O8)) | H8: =IF($O8="","",INDEX('Auto Process'!$AJ:$AJ,$O8)) | I8: =IF($O8="","",INDEX('Auto Process'!$AK:$AK,$O8)) | J8: =IF($O8="","",INDEX('Auto Process'!$AL:$AL,$O8)) | K8: =IF($O8="","",INDEX('Auto Process'!$AM:$AM,$O8)) | L8: =IF($O8="","",INDEX('Auto Process'!$AN:$AN,$O8)) | M8: =IF($O8="","",INDEX('Auto Process'!$AO:$AO,$O8)) | O8: =IFERROR(_xlfn.AGGREGATE(15,6,ROW('Auto Process'!$D$4:$D$503)/('Auto Process'!$D$4:$D$503="Panel Details"),ROW()-1),"")
A9: =IF($O9="","",INDEX('Auto Process'!$AC:$AC,$O9)) | B9: =IF($O9="","",INDEX('Auto Process'!$AD:$AD,$O9)) | C9: =IF($O9="","",INDEX('Auto Process'!$AE:$AE,$O9)) | D9: =IF($O9="","",INDEX('Auto Process'!$AF:$AF,$O9)) | E9: =IF($O9="","",INDEX('Auto Process'!$AG:$AG,$O9)) | F9: =IF($O9="","",INDEX('Auto Process'!$AH:$AH,$O9)) | G9: =IF($O9="","",INDEX('Auto Process'!$AI:$AI,$O9)) | H9: =IF($O9="","",INDEX('Auto Process'!$AJ:$AJ,$O9)) | I9: =IF($O9="","",INDEX('Auto Process'!$AK:$AK,$O9)) | J9: =IF($O9="","",INDEX('Auto Process'!$AL:$AL,$O9)) | K9: =IF($O9="","",INDEX('Auto Process'!$AM:$AM,$O9)) | L9: =IF($O9="","",INDEX('Auto Process'!$AN:$AN,$O9)) | M9: =IF($O9="","",INDEX('Auto Process'!$AO:$AO,$O9)) | O9: =IFERROR(_xlfn.AGGREGATE(15,6,ROW('Auto Process'!$D$4:$D$503)/('Auto Process'!$D$4:$D$503="Panel Details"),ROW()-1),"")
A10: =IF($O10="","",INDEX('Auto Process'!$AC:$AC,$O10)) | B10: =IF($O10="","",INDEX('Auto Process'!$AD:$AD,$O10)) | C10: =IF($O10="","",INDEX('Auto Process'!$AE:$AE,$O10)) | D10: =IF($O10="","",INDEX('Auto Process'!$AF:$AF,$O10)) | E10: =IF($O10="","",INDEX('Auto Process'!$AG:$AG,$O10)) | F10: =IF($O10="","",INDEX('Auto Process'!$AH:$AH,$O10)) | G10: =IF($O10="","",INDEX('Auto Process'!$AI:$AI,$O10)) | H10: =IF($O10="","",INDEX('Auto Process'!$AJ:$AJ,$O10)) | I10: =IF($O10="","",INDEX('Auto Process'!$AK:$AK,$O10)) | J10: =IF($O10="","",INDEX('Auto Process'!$AL:$AL,$O10)) | K10: =IF($O10="","",INDEX('Auto Process'!$AM:$AM,$O10)) | L10: =IF($O10="","",INDEX('Auto Process'!$AN:$AN,$O10)) | M10: =IF($O10="","",INDEX('Auto Process'!$AO:$AO,$O10)) | O10: =IFERROR(_xlfn.AGGREGATE(15,6,ROW('Auto Process'!$D$4:$D$503)/('Auto Process'!$D$4:$D$503="Panel Details"),ROW()-1),"")
A11: =IF($O11="","",INDEX('Auto Process'!$AC:$AC,$O11)) | B11: =IF($O11="","",INDEX('Auto Process'!$AD:$AD,$O11)) | C11: =IF($O11="","",INDEX('Auto Process'!$AE:$AE,$O11)) | D11: =IF($O11="","",INDEX('Auto Process'!$AF:$AF,$O11)) | E11: =IF($O11="","",INDEX('Auto Process'!$AG:$AG,$O11)) | F11: =IF($O11="","",INDEX('Auto Process'!$AH:$AH,$O11)) | G11: =IF($O11="","",INDEX('Auto Process'!$AI:$AI,$O11)) | H11: =IF($O11="","",INDEX('Auto Process'!$AJ:$AJ,$O11)) | I11: =IF($O11="","",INDEX('Auto Process'!$AK:$AK,$O11)) | J11: =IF($O11="","",INDEX('Auto Process'!$AL:$AL,$O11)) | K11: =IF($O11="","",INDEX('Auto Process'!$AM:$AM,$O11)) | L11: =IF($O11="","",INDEX('Auto Process'!$AN:$AN,$O11)) | M11: =IF($O11="","",INDEX('Auto Process'!$AO:$AO,$O11)) | O11: =IFERROR(_xlfn.AGGREGATE(15,6,ROW('Auto Process'!$D$4:$D$503)/('Auto Process'!$D$4:$D$503="Panel Details"),ROW()-1),"")
A12: =IF($O12="","",INDEX('Auto Process'!$AC:$AC,$O12)) | B12: =IF($O12="","",INDEX('Auto Process'!$AD:$AD,$O12)) | C12: =IF($O12="","",INDEX('Auto Process'!$AE:$AE,$O12)) | D12: =IF($O12="","",INDEX('Auto Process'!$AF:$AF,$O12)) | E12: =IF($O12="","",INDEX('Auto Process'!$AG:$AG,$O12)) | F12: =IF($O12="","",INDEX('Auto Process'!$AH:$AH,$O12)) | G12: =IF($O12="","",INDEX('Auto Process'!$AI:$AI,$O12)) | H12: =IF($O12="","",INDEX('Auto Process'!$AJ:$AJ,$O12)) | I12: =IF($O12="","",INDEX('Auto Process'!$AK:$AK,$O12)) | J12: =IF($O12="","",INDEX('Auto Process'!$AL:$AL,$O12)) | K12: =IF($O12="","",INDEX('Auto Process'!$AM:$AM,$O12)) | L12: =IF($O12="","",INDEX('Auto Process'!$AN:$AN,$O12)) | M12: =IF($O12="","",INDEX('Auto Process'!$AO:$AO,$O12)) | O12: =IFERROR(_xlfn.AGGREGATE(15,6,ROW('Auto Process'!$D$4:$D$503)/('Auto Process'!$D$4:$D$503="Panel Details"),ROW()-1),"")
A13: =IF($O13="","",INDEX('Auto Process'!$AC:$AC,$O13)) | B13: =IF($O13="","",INDEX('Auto Process'!$AD:$AD,$O13)) | C13: =IF($O13="","",INDEX('Auto Process'!$AE:$AE,$O13)) | D13: =IF($O13="","",INDEX('Auto Process'!$AF:$AF,$O13)) | E13: =IF($O13="","",INDEX('Auto Process'!$AG:$AG,$O13)) | F13: =IF($O13="","",INDEX('Auto Process'!$AH:$AH,$O13)) | G13: =IF($O13="","",INDEX('Auto Process'!$AI:$AI,$O13)) | H13: =IF($O13="","",INDEX('Auto Process'!$AJ:$AJ,$O13)) | I13: =IF($O13="","",INDEX('Auto Process'!$AK:$AK,$O13)) | J13: =IF($O13="","",INDEX('Auto Process'!$AL:$AL,$O13)) | K13: =IF($O13="","",INDEX('Auto Process'!$AM:$AM,$O13)) | L13: =IF($O13="","",INDEX('Auto Process'!$AN:$AN,$O13)) | M13: =IF($O13="","",INDEX('Auto Process'!$AO:$AO,$O13)) | O13: =IFERROR(_xlfn.AGGREGATE(15,6,ROW('Auto Process'!$D$4:$D$503)/('Auto Process'!$D$4:$D$503="Panel Details"),ROW()-1),"")
... A501: =IF($O501="","",INDEX('Auto Process'!$AC:$AC,$O501)) | B501: =IF($O501="","",INDEX('Auto Process'!$AD:$AD,$O501)) | C501: =IF($O501="","",INDEX('Auto Process'!$AE:$AE,$O501)) | D501: =IF($O501="","",INDEX('Auto Process'!$AF:$AF,$O501)) | E501: =IF($O501="","",INDEX('Auto Process'!$AG:$AG,$O501)) | F501: =IF($O501="","",INDEX('Auto Process'!$AH:$AH,$O501)) | G501: =IF($O501="","",INDEX('Auto Process'!$AI:$AI,$O501)) | H501: =IF($O501="","",INDEX('Auto Process'!$AJ:$AJ,$O501)) | I501: =IF($O501="","",INDEX('Auto Process'!$AK:$AK,$O501)) | J501: =IF($O501="","",INDEX('Auto Process'!$AL:$AL,$O501)) | K501: =IF($O501="","",INDEX('Auto Process'!$AM:$AM,$O501)) | L501: =IF($O501="","",INDEX('Auto Process'!$AN:$AN,$O501)) | M501: =IF($O501="","",INDEX('Auto Process'!$AO:$AO,$O501)) | O501: =IFERROR(_xlfn.AGGREGATE(15,6,ROW('Auto Process'!$D$4:$D$503)/('Auto Process'!$D$4:$D$503="Panel Details"),ROW()-1),"")

Sheet Followup
A1: Email | B1: Name | C1: Mobile | D1: Location | E1: Designation | F1: Primary skill (submitted) | G1: Secondary skill (submitted) | H1: Note | J1: srcRow
A2: =IF($J2="","",INDEX('Auto Process'!$AP:$AP,$J2)) | B2: =IF($J2="","",INDEX('Auto Process'!$AQ:$AQ,$J2)) | C2: =IF($J2="","",INDEX('Auto Process'!$AR:$AR,$J2)) | D2: =IF($J2="","",INDEX('Auto Process'!$AS:$AS,$J2)) | E2: =IF($J2="","",INDEX('Auto Process'!$AT:$AT,$J2)) | F2: =IF($J2="","",INDEX('Auto Process'!$AU:$AU,$J2)) | G2: =IF($J2="","",INDEX('Auto Process'!$AV:$AV,$J2)) | H2: =IF($J2="","",INDEX('Auto Process'!$AW:$AW,$J2)) | J2: =IFERROR(_xlfn.AGGREGATE(15,6,ROW('Auto Process'!$D$4:$D$503)/('Auto Process'!$D$4:$D$503="Followup"),ROW()-1),"")
A3: =IF($J3="","",INDEX('Auto Process'!$AP:$AP,$J3)) | B3: =IF($J3="","",INDEX('Auto Process'!$AQ:$AQ,$J3)) | C3: =IF($J3="","",INDEX('Auto Process'!$AR:$AR,$J3)) | D3: =IF($J3="","",INDEX('Auto Process'!$AS:$AS,$J3)) | E3: =IF($J3="","",INDEX('Auto Process'!$AT:$AT,$J3)) | F3: =IF($J3="","",INDEX('Auto Process'!$AU:$AU,$J3)) | G3: =IF($J3="","",INDEX('Auto Process'!$AV:$AV,$J3)) | H3: =IF($J3="","",INDEX('Auto Process'!$AW:$AW,$J3)) | J3: =IFERROR(_xlfn.AGGREGATE(15,6,ROW('Auto Process'!$D$4:$D$503)/('Auto Process'!$D$4:$D$503="Followup"),ROW()-1),"")
A4: =IF($J4="","",INDEX('Auto Process'!$AP:$AP,$J4)) | B4: =IF($J4="","",INDEX('Auto Process'!$AQ:$AQ,$J4)) | C4: =IF($J4="","",INDEX('Auto Process'!$AR:$AR,$J4)) | D4: =IF($J4="","",INDEX('Auto Process'!$AS:$AS,$J4)) | E4: =IF($J4="","",INDEX('Auto Process'!$AT:$AT,$J4)) | F4: =IF($J4="","",INDEX('Auto Process'!$AU:$AU,$J4)) | G4: =IF($J4="","",INDEX('Auto Process'!$AV:$AV,$J4)) | H4: =IF($J4="","",INDEX('Auto Process'!$AW:$AW,$J4)) | J4: =IFERROR(_xlfn.AGGREGATE(15,6,ROW('Auto Process'!$D$4:$D$503)/('Auto Process'!$D$4:$D$503="Followup"),ROW()-1),"")
A5: =IF($J5="","",INDEX('Auto Process'!$AP:$AP,$J5)) | B5: =IF($J5="","",INDEX('Auto Process'!$AQ:$AQ,$J5)) | C5: =IF($J5="","",INDEX('Auto Process'!$AR:$AR,$J5)) | D5: =IF($J5="","",INDEX('Auto Process'!$AS:$AS,$J5)) | E5: =IF($J5="","",INDEX('Auto Process'!$AT:$AT,$J5)) | F5: =IF($J5="","",INDEX('Auto Process'!$AU:$AU,$J5)) | G5: =IF($J5="","",INDEX('Auto Process'!$AV:$AV,$J5)) | H5: =IF($J5="","",INDEX('Auto Process'!$AW:$AW,$J5)) | J5: =IFERROR(_xlfn.AGGREGATE(15,6,ROW('Auto Process'!$D$4:$D$503)/('Auto Process'!$D$4:$D$503="Followup"),ROW()-1),"")
A6: =IF($J6="","",INDEX('Auto Process'!$AP:$AP,$J6)) | B6: =IF($J6="","",INDEX('Auto Process'!$AQ:$AQ,$J6)) | C6: =IF($J6="","",INDEX('Auto Process'!$AR:$AR,$J6)) | D6: =IF($J6="","",INDEX('Auto Process'!$AS:$AS,$J6)) | E6: =IF($J6="","",INDEX('Auto Process'!$AT:$AT,$J6)) | F6: =IF($J6="","",INDEX('Auto Process'!$AU:$AU,$J6)) | G6: =IF($J6="","",INDEX('Auto Process'!$AV:$AV,$J6)) | H6: =IF($J6="","",INDEX('Auto Process'!$AW:$AW,$J6)) | J6: =IFERROR(_xlfn.AGGREGATE(15,6,ROW('Auto Process'!$D$4:$D$503)/('Auto Process'!$D$4:$D$503="Followup"),ROW()-1),"")
A7: =IF($J7="","",INDEX('Auto Process'!$AP:$AP,$J7)) | B7: =IF($J7="","",INDEX('Auto Process'!$AQ:$AQ,$J7)) | C7: =IF($J7="","",INDEX('Auto Process'!$AR:$AR,$J7)) | D7: =IF($J7="","",INDEX('Auto Process'!$AS:$AS,$J7)) | E7: =IF($J7="","",INDEX('Auto Process'!$AT:$AT,$J7)) | F7: =IF($J7="","",INDEX('Auto Process'!$AU:$AU,$J7)) | G7: =IF($J7="","",INDEX('Auto Process'!$AV:$AV,$J7)) | H7: =IF($J7="","",INDEX('Auto Process'!$AW:$AW,$J7)) | J7: =IFERROR(_xlfn.AGGREGATE(15,6,ROW('Auto Process'!$D$4:$D$503)/('Auto Process'!$D$4:$D$503="Followup"),ROW()-1),"")
A8: =IF($J8="","",INDEX('Auto Process'!$AP:$AP,$J8)) | B8: =IF($J8="","",INDEX('Auto Process'!$AQ:$AQ,$J8)) | C8: =IF($J8="","",INDEX('Auto Process'!$AR:$AR,$J8)) | D8: =IF($J8="","",INDEX('Auto Process'!$AS:$AS,$J8)) | E8: =IF($J8="","",INDEX('Auto Process'!$AT:$AT,$J8)) | F8: =IF($J8="","",INDEX('Auto Process'!$AU:$AU,$J8)) | G8: =IF($J8="","",INDEX('Auto Process'!$AV:$AV,$J8)) | H8: =IF($J8="","",INDEX('Auto Process'!$AW:$AW,$J8)) | J8: =IFERROR(_xlfn.AGGREGATE(15,6,ROW('Auto Process'!$D$4:$D$503)/('Auto Process'!$D$4:$D$503="Followup"),ROW()-1),"")
A9: =IF($J9="","",INDEX('Auto Process'!$AP:$AP,$J9)) | B9: =IF($J9="","",INDEX('Auto Process'!$AQ:$AQ,$J9)) | C9: =IF($J9="","",INDEX('Auto Process'!$AR:$AR,$J9)) | D9: =IF($J9="","",INDEX('Auto Process'!$AS:$AS,$J9)) | E9: =IF($J9="","",INDEX('Auto Process'!$AT:$AT,$J9)) | F9: =IF($J9="","",INDEX('Auto Process'!$AU:$AU,$J9)) | G9: =IF($J9="","",INDEX('Auto Process'!$AV:$AV,$J9)) | H9: =IF($J9="","",INDEX('Auto Process'!$AW:$AW,$J9)) | J9: =IFERROR(_xlfn.AGGREGATE(15,6,ROW('Auto Process'!$D$4:$D$503)/('Auto Process'!$D$4:$D$503="Followup"),ROW()-1),"")
A10: =IF($J10="","",INDEX('Auto Process'!$AP:$AP,$J10)) | B10: =IF($J10="","",INDEX('Auto Process'!$AQ:$AQ,$J10)) | C10: =IF($J10="","",INDEX('Auto Process'!$AR:$AR,$J10)) | D10: =IF($J10="","",INDEX('Auto Process'!$AS:$AS,$J10)) | E10: =IF($J10="","",INDEX('Auto Process'!$AT:$AT,$J10)) | F10: =IF($J10="","",INDEX('Auto Process'!$AU:$AU,$J10)) | G10: =IF($J10="","",INDEX('Auto Process'!$AV:$AV,$J10)) | H10: =IF($J10="","",INDEX('Auto Process'!$AW:$AW,$J10)) | J10: =IFERROR(_xlfn.AGGREGATE(15,6,ROW('Auto Process'!$D$4:$D$503)/('Auto Process'!$D$4:$D$503="Followup"),ROW()-1),"")
A11: =IF($J11="","",INDEX('Auto Process'!$AP:$AP,$J11)) | B11: =IF($J11="","",INDEX('Auto Process'!$AQ:$AQ,$J11)) | C11: =IF($J11="","",INDEX('Auto Process'!$AR:$AR,$J11)) | D11: =IF($J11="","",INDEX('Auto Process'!$AS:$AS,$J11)) | E11: =IF($J11="","",INDEX('Auto Process'!$AT:$AT,$J11)) | F11: =IF($J11="","",INDEX('Auto Process'!$AU:$AU,$J11)) | G11: =IF($J11="","",INDEX('Auto Process'!$AV:$AV,$J11)) | H11: =IF($J11="","",INDEX('Auto Process'!$AW:$AW,$J11)) | J11: =IFERROR(_xlfn.AGGREGATE(15,6,ROW('Auto Process'!$D$4:$D$503)/('Auto Process'!$D$4:$D$503="Followup"),ROW()-1),"")
A12: =IF($J12="","",INDEX('Auto Process'!$AP:$AP,$J12)) | B12: =IF($J12="","",INDEX('Auto Process'!$AQ:$AQ,$J12)) | C12: =IF($J12="","",INDEX('Auto Process'!$AR:$AR,$J12)) | D12: =IF($J12="","",INDEX('Auto Process'!$AS:$AS,$J12)) | E12: =IF($J12="","",INDEX('Auto Process'!$AT:$AT,$J12)) | F12: =IF($J12="","",INDEX('Auto Process'!$AU:$AU,$J12)) | G12: =IF($J12="","",INDEX('Auto Process'!$AV:$AV,$J12)) | H12: =IF($J12="","",INDEX('Auto Process'!$AW:$AW,$J12)) | J12: =IFERROR(_xlfn.AGGREGATE(15,6,ROW('Auto Process'!$D$4:$D$503)/('Auto Process'!$D$4:$D$503="Followup"),ROW()-1),"")
A13: =IF($J13="","",INDEX('Auto Process'!$AP:$AP,$J13)) | B13: =IF($J13="","",INDEX('Auto Process'!$AQ:$AQ,$J13)) | C13: =IF($J13="","",INDEX('Auto Process'!$AR:$AR,$J13)) | D13: =IF($J13="","",INDEX('Auto Process'!$AS:$AS,$J13)) | E13: =IF($J13="","",INDEX('Auto Process'!$AT:$AT,$J13)) | F13: =IF($J13="","",INDEX('Auto Process'!$AU:$AU,$J13)) | G13: =IF($J13="","",INDEX('Auto Process'!$AV:$AV,$J13)) | H13: =IF($J13="","",INDEX('Auto Process'!$AW:$AW,$J13)) | J13: =IFERROR(_xlfn.AGGREGATE(15,6,ROW('Auto Process'!$D$4:$D$503)/('Auto Process'!$D$4:$D$503="Followup"),ROW()-1),"")
... A501: =IF($J501="","",INDEX('Auto Process'!$AP:$AP,$J501)) | B501: =IF($J501="","",INDEX('Auto Process'!$AQ:$AQ,$J501)) | C501: =IF($J501="","",INDEX('Auto Process'!$AR:$AR,$J501)) | D501: =IF($J501="","",INDEX('Auto Process'!$AS:$AS,$J501)) | E501: =IF($J501="","",INDEX('Auto Process'!$AT:$AT,$J501)) | F501: =IF($J501="","",INDEX('Auto Process'!$AU:$AU,$J501)) | G501: =IF($J501="","",INDEX('Auto Process'!$AV:$AV,$J501)) | H501: =IF($J501="","",INDEX('Auto Process'!$AW:$AW,$J501)) | J501: =IFERROR(_xlfn.AGGREGATE(15,6,ROW('Auto Process'!$D$4:$D$503)/('Auto Process'!$D$4:$D$503="Followup"),ROW()-1),"")

Sheet MasterPanel
A1: id | B1: email | C1: Panel Name | D1: Designation | E1: New Designation | F1: Contact | G1: Location | H1: R1/R2/R3 | I1: Skill | J1: Skill Group | K1: Panel Approved ?
A2: 1823 | B2: aaabishek@deloitte.com | C2: Abishek Abishek | D2: Senior Consultant | E2: L45 - AI and Data Science Engineer III | F2: 917867000000 | G2: Bengaluru | H2: R1 | I2: Machine Learning | J2: DS | K2: Y
A3: 1824 | B3: aaabishek@deloitte.com | C3: Abishek Abishek | D3: Senior Consultant | E3: L45 - AI and Data Science Engineer III | F3: 917867000000 | G3: Bengaluru | H3: R1 | I3: MLOPs | J3: DS | K3: Y
A4: 1825 | B4: aaabishek@deloitte.com | C4: Abishek, S A | D4: Senior Consultant | E4: L45 - AI and Data Science Engineer III | F4: 917867000000 | G4: Bengaluru | H4: R1 | I4: Gen AI | J4: AI | K4: Y
A5: 1826 | B5: aajazshaikh@deloitte.com | C5: Afnan Shaikh | D5: Senior Consultant | E5: Senior Consultant | F5: 7972722106 | G5: Pune | H5: R1 | I5: AWS - Admin | J5: Amazon Web Services (AWS) | K5: Y
A6: 1827 | B6: aajazshaikh@deloitte.com | C6: Afnan Shaikh | D6: Senior Consultant | E6: Senior Consultant | F6: 7972722106 | G6: Pune | H6: R1 | I6: Big Data Admin | J6: Big Data | K6: Y
A7: 1828 | B7: aajazshaikh@deloitte.com | C7: Ajaz Shaikh, Afnan | D7: Senior Consultant | E7: Senior Consultant | F7: 7972722106 | G7: Pune | H7: R1 | I7: Full Stack Development - Python | J7: Python | K7: Y
A8: 1829 | B8: aamadan@deloitte.com | C8: Aanchal Madan | D8: Senior Consultant | E8: L45 - Analytics and Insights Engineer III | F8: 9642047700 | G8: Hyderabad | H8: R1 | I8: Google Cloud Platform (GCP) - Architect | J8: Google Cloud Platform (GCP) | K8: Y
A9: 1830 | B9: aamadan@deloitte.com | C9: Aanchal Madan | D9: Senior Consultant | E9: L45 - Analytics and Insights Engineer III | F9: 9642047700 | G9: Hyderabad | H9: R1 | I9: Product Management | J9: Functional | K9: Y
A10: 1831 | B10: aamadan@deloitte.com | C10: Aanchal Madan | D10: Senior Consultant | E10: L45 - Analytics and Insights Engineer III | F10: 9642047700 | G10: Hyderabad | H10: R1 | I10: SQL | J10: SQL | K10: Y
A11: 1832 | B11: aamadan@deloitte.com | C11: Madan, Aanchal | D11: Senior Consultant | E11: L45 - Analytics and Insights Engineer III | F11: 9642047700 | G11: Hyderabad | H11: R1 | I11: Business Analysis | J11: Functional | K11: Y
A12: 1834 | B12: aamadan@deloitte.com | C12: Aanchal Madan | D12: Senior Consultant | E12: L45 - Analytics and Insights Engineer III | F12: 9642047700 | G12: Hyderabad | H12: R1 | I12: Data Analysis | J12: Data | K12: Y
A13: 1835 | B13: aanair@deloitte.com | C13: Nair, Aarthi | D13: Senior Consultant | E13: L45 - Data Management Engineer III | F13: 9742708232 | G13: Bengaluru | H13: R1 | I13: PL/SQL | J13: SQL | K13: Y
... A46: 1869 | B46: abaldewa@deloitte.com | C46: Ankita Baldewa | D46: Senior Consultant | E46: L45 - AI and Data Solutions Engineer | F46: 9903062924 | G46: Gurgaon | H46: R1 | I46: PL/SQL | J46: SQL | K46: Y
A47: 1870 | B47: abbiswal@deloitte.com | C47: Biswal, Abhishek | D47: Manager | E47: 0 | F47: 0 | G47: Bengaluru | H47: R2 | I47: Hadoop | J47: Big Data | K47: Y
A48: 1871 | B48: abbiswal@deloitte.com | C48: Biswal, Abhishek | D48: Manager | E48: 0 | F48: 0 | G48: Bengaluru | H48: R2 | I48: Spark | J48: Big Data | K48: Y
A49: 1872 | B49: abbiswal@deloitte.com | C49: Biswal, Abhishek | D49: Manager | E49: 0 | F49: 0 | G49: Bengaluru | H49: R2 | I49: Power BI | J49: Visualization | K49: Y
A50: 1873 | B50: abbiswal@deloitte.com | C50: Biswal, Abhishek | D50: Manager | E50: 0 | F50: 0 | G50: Bengaluru | H50: R2 | I50: Pyspark | J50: Big Data | K50: Y
A51: 1874 | B51: abdrahaman@deloitte.com | C51: Rahaman, Abdur | D51: Senior Consultant | E51: L35 - AI and Data Science Engineer II | F51: 0 | G51: Bengaluru | H51: R1 | I51: Gen AI | J51: AI | K51: Y
A52: 1875 | B52: abdrahaman@deloitte.com | C52: Rahaman, Abdur | D52: Senior Consultant | E52: L35 - AI and Data Science Engineer II | F52: 0 | G52: Bengaluru | H52: R1 | I52: Data Science | J52: DS | K52: Y
A53: 1876 | B53: abhiawasthi@deloitte.com | C53: Abhishek Awasthi | D53: Manager | E53: L55 - Lead Data Engineer II | F53: 9769671026 | G53: Bengaluru | H53: R2 | I53: Informatica Intelligent Cloud Services (IICS) | J53: Informatica | K53: Y
A54: 1877 | B54: abhichaubey@deloitte.com | C54: Abhishek Chaubey | D54: Consultant | E54: L35 - Data Engineer II | F54: 7974408878 | G54: Hyderabad | H54: R1 | I54: DBT | J54: ETL | K54: Y
A55: 1878 | B55: abhichaubey@deloitte.com | C55: Chaubey, Abhishek | D55: Consultant | E55: L35 - Data Engineer II | F55: 7974408878 | G55: Hyderabad | H55: R1 | I55: Snowflake - Developer | J55: Snowflake | K55: Y
A56: 1879 | B56: abhijimishra@deloitte.com | C56: Mishra, Abhijit | D56: Manager | E56: L55 - Lead AI and Data Solutions Engineer II | F56: 7459796521 | G56: Mumbai | H56: R2 | I56: Google Cloud Platform (GCP) - Data Engineer | J56: Google Cloud Platform (GCP) | K56: Y
A57: 1880 | B57: abhijimishra@deloitte.com | C57: Mishra, Abhijit | D57: Manager | E57: L55 - Lead AI and Data Solutions Engineer II | F57: 7459796521 | G57: Mumbai | H57: R2 | I57: Hadoop | J57: Big Data | K57: Y
A58: 1881 | B58: abhijimishra@deloitte.com | C58: Mishra, Abhijit | D58: Manager | E58: L55 - Lead AI and Data Solutions Engineer II | F58: 7459796521 | G58: Mumbai | H58: R2 | I58: SAP BODS | J58: SAP | K58: Y
A59: 1882 | B59: abhijimishra@deloitte.com | C59: Mishra, Abhijit | D59: Manager | E59: L55 - Lead AI and Data Solutions Engineer II | F59: 7459796521 | G59: Mumbai | H59: R2 | I59: Machine Learning | J59: DS | K59: Y
A60: 1883 | B60: abhijimishra@deloitte.com | C60: Mishra, Abhijit | D60: Manager | E60: L55 - Lead AI and Data Solutions Engineer II | F60: 7459796521 | G60: Mumbai | H60: R2 | I60: Gen AI | J60: AI | K60: Y
A61: 1884 | B61: abhijimishra@deloitte.com | C61: Mishra, Abhijit | D61: Manager | E61: L55 - Lead AI and Data Solutions Engineer II | F61: 7459796521 | G61: Mumbai | H61: R2 | I61: Agentic AI | J61: AI | K61: Y
A62: 1885 | B62: abhijnandi@deloitte.com | C62: Nandi, Abhijeet | D62: Manager | E62: L55 - Lead Analytics and Insights Engineer II | F62: 8123001414 | G62: Bengaluru | H62: R2 | I62: PL/SQL | J62: SQL | K62: Y
... A184: 2015 | B184: aindubajranglal@deloitte.com | C184: Aggarwal, Indu | D184: Senior Consultant | E184: L45 - Analytics and Insights Engineer III | F184: 9099092748 | G184: Pune | H184: R1 | I184: Tableau | J184: Visualization | K184: Y
A185: 2016 | B185: ajadia@deloitte.com | C185: Jadia, Aditya | D185: Senior Consultant | E185: Senior Consultant | F185: '+919407273786 | G185: Hyderabad | H185: R1 | I185: Snowflake - Developer | J185: Snowflake | K185: Y
A186: 2017 | B186: ajadia@deloitte.com | C186: Jadia, Aditya | D186: Senior Consultant | E186: Senior Consultant | F186: '+919407273786 | G186: Hyderabad | H186: R1 | I186: PL/SQL | J186: SQL | K186: Y
A187: 2018 | B187: ajadia@deloitte.com | C187: Aditya Jadia | D187: Senior Consultant | E187: Senior Consultant | F187: '+919407273786 | G187: Hyderabad | H187: R1 | I187: Python Data Engineering | J187: Python | K187: Y
A188: 2019 | B188: ajakrishnan@deloitte.com | C188: Ajay Krishnan Krishnan | D188: Manager | E188: L55 - Lead AI and Data Solutions Engineer II | F188: 918979000000 | G188: Chennai | H188: R2 | I188: AWS - Data Architect | J188: Amazon Web Services (AWS) | K188: Y
A189: 2020 | B189: ajakrishnan@deloitte.com | C189: Ajay Krishnan Krishnan | D189: Manager | E189: L55 - Lead AI and Data Solutions Engineer II | F189: 918979000000 | G189: Chennai | H189: R2 | I189: DevOps | J189: DevOps | K189: Y
A190: 2021 | B190: ajakrishnan@deloitte.com | C190: Krishnan, Ajay | D190: Manager | E190: L55 - Lead AI and Data Solutions Engineer II | F190: 918979000000 | G190: Chennai | H190: R2 | I190: Data Science | J190: DS | K190: Y
A191: 2022 | B191: ajakrishnan@deloitte.com | C191: Krishnan, Ajay | D191: Manager | E191: L55 - Lead AI and Data Solutions Engineer II | F191: 918979000000 | G191: Chennai | H191: R2 | I191: Machine Learning | J191: DS | K191: Y
A192: 2023 | B192: ajakrishnan@deloitte.com | C192: Krishnan, Ajay | D192: Manager | E192: L55 - Lead AI and Data Solutions Engineer II | F192: 918979000000 | G192: Chennai | H192: R2 | I192: Gen AI | J192: AI | K192: Y
A193: 2024 | B193: ajakrishnan@deloitte.com | C193: Krishnan, Ajay | D193: Manager | E193: L55 - Lead AI and Data Solutions Engineer II | F193: 8978986417 | G193: Chennai | H193: R2 | I193: Agentic AI | J193: AI | K193: Y
...

Sheet Survey Response
A1: ID | B1: Start time | C1: Completion time | D1: Email | E1: Name | F1: Last modified time | G1: Mobile Number | H1: Please select your location | I1: Are you available to conduct interviews scheduled for the weekend of September 26th, 2026? | J1: Are you taking for the first time? | K1: Kindly select your primary skill | L1: Kindly select your secondary skill | M1: Please select your designation

Sheet Auto Process
A1: AUTO PROCESS (Chennai) v3 - simplified. Number of Slots is always 8 (fixed, per instruction - no duration parsing). Routing: check Primary skill first (approved AND still has capacity vs Gap Sheet's Ask, first-come-first-served by completion time) - if it fits, place there. Else check Secondary skill the same way. Else -> Followup. Capacity is tracked here directly against the Ask numbers (not the live Gap Sheet Available column) to avoid a circular reference, since Panel Details itself depends on this routing.
A3: Survey(check) | B3: Auto(check) | C3: Check | D3: Route | E3: Is Latest | F3: Survey ID | G3: Completion | H3: Email (norm) | I3: Available raw | J3: Primary raw | K3: Mapped Primary | L3: Secondary raw | M3: Mapped Secondary | N3: Designation | O3: Level | P3: PrimaryApproved? | Q3: PrimaryAsk | R3: PrimaryKey | S3: PriorMatchesPrimary | T3: PrimaryRequired? | U3: SecondaryApproved? | V3: SecondaryAsk | W3: SecondaryKey | X3: PriorMatchesSecondary | Y3: SecondaryRequired? | Z3: MatchedSkill | AA3: MatchedKey | AB3: Comment | AC3: ID | AD3: Email | AE3: Name | AF3: Mobile | AG3: Primary Skill | AH3: Secondary Skill | AI3: Location | AJ3: Designation | AK3: Level | AL3: Number of Slots | AM3: Comments | AN3: In Master Panel List? | AO3: Panel to Travel | AP3: Email | AQ3: Name | AR3: Mobile | AS3: Location | AT3: Designation | AU3: Primary skill (submitted) | AV3: Secondary skill (submitted) | AW3: Note
A4: =IF('Survey Response'!$D2="","",'Survey Response'!$A2&"|"&LOWER(TRIM('Survey Response'!$D2))) | B4: =IF($H4="","",$F4&"|"&$H4) | C4: =IF($H4="","",$A4=$B4) | D4: =IF($H4="","",IF($E4<>"Yes","Superseded",IF($I4<>"Yes, I'm available for in-person interviews at Chennai","Not Available",IF($Z4<>"","Panel Details","Followup")))) | E4: =IF($H4="","",IF(SUMPRODUCT(($H$4:$H$503=$H4)*(($G$4:$G$503>$G4)+($G$4:$G$503=$G4)*($F$4:$F$503>$F4)))=0,"Yes","No")) | F4: =IF('Survey Response'!$D2="","",INT('Survey Response'!$A2)) | G4: =IF('Survey Response'!$D2="","",'Survey Response'!$C2) | H4: =IF('Survey Response'!$D2="","",LOWER(TRIM('Survey Response'!$D2))) | I4: =IF($H4="","",'Survey Response'!$I2) | J4: =IF($H4="","",'Survey Response'!$K2) | K4: =IF($J4="","",IF(COUNTIF('Skill Mapping'!$A$2:$A$7,TRIM($J4))=0,"",INDEX('Skill Mapping'!$B$2:$B$7,MATCH(TRIM($J4),'Skill Mapping'!$A$2:$A$7,0)))) | L4: =IF($H4="","",'Survey Response'!$L2) | M4: =IF($L4="","",IF(COUNTIF('Skill Mapping'!$A$2:$A$7,TRIM($L4))=0,"",INDEX('Skill Mapping'!$B$2:$B$7,MATCH(TRIM($L4),'Skill Mapping'!$A$2:$A$7,0)))) | N4: =IF($H4="","",'Survey Response'!$M2) | O4: =IF($H4="","",IF('Survey Response'!$M2="Manager","R2","R1")) | P4: =IF($K4="","No",IF(COUNTIFS(MasterPanel!$B:$B,$H4,MasterPanel!$I:$I,$K4,MasterPanel!$K:$K,"Y")>0,"Yes","No")) -> No | Q4: =IF($K4="",0,IF(COUNTIF('Gap Sheet'!$A$6:$A$11,TRIM($J4))=0,0,IF($O4="R1",INDEX('Gap Sheet'!$C$6:$C$11,MATCH(TRIM($J4),'Gap Sheet'!$A$6:$A$11,0)),INDEX('Gap Sheet'!$G$6:$G$11,MATCH(TRIM($J4),'Gap Sheet'!$A$6:$A$11,0))))) -> 0 | R4: =IF($K4="","",$K4&"|"&$O4) | S4: =0 -> 0 | T4: =IF(OR($I4<>"Yes, I'm available for in-person interviews at Chennai",$E4<>"Yes",$P4<>"Yes"),"No",IF(($Q4-$S4)>0,"Yes","No")) -> No | U4: =IF($M4="","No",IF(COUNTIFS(MasterPanel!$B:$B,$H4,MasterPanel!$I:$I,$M4,MasterPanel!$K:$K,"Y")>0,"Yes","No")) -> No | V4: =IF($M4="",0,IF(COUNTIF('Gap Sheet'!$A$6:$A$11,TRIM($L4))=0,0,IF($O4="R1",INDEX('Gap Sheet'!$C$6:$C$11,MATCH(TRIM($L4),'Gap Sheet'!$A$6:$A$11,0)),INDEX('Gap Sheet'!$G$6:$G$11,MATCH(TRIM($L4),'Gap Sheet'!$A$6:$A$11,0))))) -> 0 | W4: =IF($M4="","",$M4&"|"&$O4) | X4: =0 -> 0 | Y4: =IF(OR($I4<>"Yes, I'm available for in-person interviews at Chennai",$E4<>"Yes",$T4="Yes",$U4<>"Yes"),"No",IF(($V4-$X4)>0,"Yes","No")) -> No | Z4: =IF($T4="Yes","Primary",IF($Y4="Yes","Secondary","")) | AA4: =IF($Z4="Primary",$R4,IF($Z4="Secondary",$W4,"")) | AB4: =IF($Z4="Primary","Matched on primary skill",IF($Z4="Secondary","Matched on secondary skill (primary not approved or not required)","")) | AC4: =IF($D4="Panel Details",$F4,"") | AD4: =IF($D4="Panel Details",'Survey Response'!$D2,"") | AE4: =IF($D4="Panel Details",'Survey Response'!$E2,"") | AF4: =IF($D4="Panel Details",'Survey Response'!$G2,"") | AG4: =IF($D4="Panel Details",IF($Z4="Primary",$J4,$L4),"") | AH4: =IF($D4="Panel Details",IF($Z4="Primary",$L4,$J4),"") | AI4: =IF($D4="Panel Details",'Survey Response'!$H2,"") | AJ4: =IF($D4="Panel Details",'Survey Response'!$M2,"") | AK4: =IF($D4="Panel Details",$O4,"") | AL4: =IF($D4="Panel Details",8,"") | AM4: =IF($D4="Panel Details",$AB4,"") | AN4: =IF($D4="Panel Details","Yes","") | AP4: =IF($D4="Followup",'Survey Response'!$D2,"") | AQ4: =IF($D4="Followup",'Survey Response'!$E2,"") | AR4: =IF($D4="Followup",'Survey Response'!$G2,"") | AS4: =IF($D4="Followup",'Survey Response'!$H2,"") | AT4: =IF($D4="Followup",'Survey Response'!$M2,"") | AU4: =IF($D4="Followup",'Survey Response'!$K2,"") | AV4: =IF($D4="Followup",'Survey Response'!$L2,"") | AW4: =IF($D4="Followup",IF(AND($P4<>"Yes",$U4<>"Yes"),"Not approved for primary or secondary skill","Approved, but skill(s) no longer have capacity (fully staffed)"),"")
A5: =IF('Survey Response'!$D3="","",'Survey Response'!$A3&"|"&LOWER(TRIM('Survey Response'!$D3))) | B5: =IF($H5="","",$F5&"|"&$H5) | C5: =IF($H5="","",$A5=$B5) | D5: =IF($H5="","",IF($E5<>"Yes","Superseded",IF($I5<>"Yes, I'm available for in-person interviews at Chennai","Not Available",IF($Z5<>"","Panel Details","Followup")))) | E5: =IF($H5="","",IF(SUMPRODUCT(($H$4:$H$503=$H5)*(($G$4:$G$503>$G5)+($G$4:$G$503=$G5)*($F$4:$F$503>$F5)))=0,"Yes","No")) | F5: =IF('Survey Response'!$D3="","",INT('Survey Response'!$A3)) | G5: =IF('Survey Response'!$D3="","",'Survey Response'!$C3) | H5: =IF('Survey Response'!$D3="","",LOWER(TRIM('Survey Response'!$D3))) | I5: =IF($H5="","",'Survey Response'!$I3) | J5: =IF($H5="","",'Survey Response'!$K3) | K5: =IF($J5="","",IF(COUNTIF('Skill Mapping'!$A$2:$A$7,TRIM($J5))=0,"",INDEX('Skill Mapping'!$B$2:$B$7,MATCH(TRIM($J5),'Skill Mapping'!$A$2:$A$7,0)))) | L5: =IF($H5="","",'Survey Response'!$L3) | M5: =IF($L5="","",IF(COUNTIF('Skill Mapping'!$A$2:$A$7,TRIM($L5))=0,"",INDEX('Skill Mapping'!$B$2:$B$7,MATCH(TRIM($L5),'Skill Mapping'!$A$2:$A$7,0)))) | N5: =IF($H5="","",'Survey Response'!$M3) | O5: =IF($H5="","",IF('Survey Response'!$M3="Manager","R2","R1")) | P5: =IF($K5="","No",IF(COUNTIFS(MasterPanel!$B:$B,$H5,MasterPanel!$I:$I,$K5,MasterPanel!$K:$K,"Y")>0,"Yes","No")) -> No | Q5: =IF($K5="",0,IF(COUNTIF('Gap Sheet'!$A$6:$A$11,TRIM($J5))=0,0,IF($O5="R1",INDEX('Gap Sheet'!$C$6:$C$11,MATCH(TRIM($J5),'Gap Sheet'!$A$6:$A$11,0)),INDEX('Gap Sheet'!$G$6:$G$11,MATCH(TRIM($J5),'Gap Sheet'!$A$6:$A$11,0))))) -> 0 | R5: =IF($K5="","",$K5&"|"&$O5) | S5: =IF($R5="",0,COUNTIF($AA$4:$AA4,$R5)) -> 0 | T5: =IF(OR($I5<>"Yes, I'm available for in-person interviews at Chennai",$E5<>"Yes",$P5<>"Yes"),"No",IF(($Q5-$S5)>0,"Yes","No")) -> No | U5: =IF($M5="","No",IF(COUNTIFS(MasterPanel!$B:$B,$H5,MasterPanel!$I:$I,$M5,MasterPanel!$K:$K,"Y")>0,"Yes","No")) -> No | V5: =IF($M5="",0,IF(COUNTIF('Gap Sheet'!$A$6:$A$11,TRIM($L5))=0,0,IF($O5="R1",INDEX('Gap Sheet'!$C$6:$C$11,MATCH(TRIM($L5),'Gap Sheet'!$A$6:$A$11,0)),INDEX('Gap Sheet'!$G$6:$G$11,MATCH(TRIM($L5),'Gap Sheet'!$A$6:$A$11,0))))) -> 0 | W5: =IF($M5="","",$M5&"|"&$O5) | X5: =IF($W5="",0,COUNTIF($AA$4:$AA4,$W5)) -> 0 | Y5: =IF(OR($I5<>"Yes, I'm available for in-person interviews at Chennai",$E5<>"Yes",$T5="Yes",$U5<>"Yes"),"No",IF(($V5-$X5)>0,"Yes","No")) -> No | Z5: =IF($T5="Yes","Primary",IF($Y5="Yes","Secondary","")) | AA5: =IF($Z5="Primary",$R5,IF($Z5="Secondary",$W5,"")) | AB5: =IF($Z5="Primary","Matched on primary skill",IF($Z5="Secondary","Matched on secondary skill (primary not approved or not required)","")) | AC5: =IF($D5="Panel Details",$F5,"") | AD5: =IF($D5="Panel Details",'Survey Response'!$D3,"") | AE5: =IF($D5="Panel Details",'Survey Response'!$E3,"") | AF5: =IF($D5="Panel Details",'Survey Response'!$G3,"") | AG5: =IF($D5="Panel Details",IF($Z5="Primary",$J5,$L5),"") | AH5: =IF($D5="Panel Details",IF($Z5="Primary",$L5,$J5),"") | AI5: =IF($D5="Panel Details",'Survey Response'!$H3,"") | AJ5: =IF($D5="Panel Details",'Survey Response'!$M3,"") | AK5: =IF($D5="Panel Details",$O5,"") | AL5: =IF($D5="Panel Details",8,"") | AM5: =IF($D5="Panel Details",$AB5,"") | AN5: =IF($D5="Panel Details","Yes","") | AP5: =IF($D5="Followup",'Survey Response'!$D3,"") | AQ5: =IF($D5="Followup",'Survey Response'!$E3,"") | AR5: =IF($D5="Followup",'Survey Response'!$G3,"") | AS5: =IF($D5="Followup",'Survey Response'!$H3,"") | AT5: =IF($D5="Followup",'Survey Response'!$M3,"") | AU5: =IF($D5="Followup",'Survey Response'!$K3,"") | AV5: =IF($D5="Followup",'Survey Response'!$L3,"") | AW5: =IF($D5="Followup",IF(AND($P5<>"Yes",$U5<>"Yes"),"Not approved for primary or secondary skill","Approved, but skill(s) no longer have capacity (fully staffed)"),"")
A6: =IF('Survey Response'!$D4="","",'Survey Response'!$A4&"|"&LOWER(TRIM('Survey Response'!$D4))) | B6: =IF($H6="","",$F6&"|"&$H6) | C6: =IF($H6="","",$A6=$B6) | D6: =IF($H6="","",IF($E6<>"Yes","Superseded",IF($I6<>"Yes, I'm available for in-person interviews at Chennai","Not Available",IF($Z6<>"","Panel Details","Followup")))) | E6: =IF($H6="","",IF(SUMPRODUCT(($H$4:$H$503=$H6)*(($G$4:$G$503>$G6)+($G$4:$G$503=$G6)*($F$4:$F$503>$F6)))=0,"Yes","No")) | F6: =IF('Survey Response'!$D4="","",INT('Survey Response'!$A4)) | G6: =IF('Survey Response'!$D4="","",'Survey Response'!$C4) | H6: =IF('Survey Response'!$D4="","",LOWER(TRIM('Survey Response'!$D4))) | I6: =IF($H6="","",'Survey Response'!$I4) | J6: =IF($H6="","",'Survey Response'!$K4) | K6: =IF($J6="","",IF(COUNTIF('Skill Mapping'!$A$2:$A$7,TRIM($J6))=0,"",INDEX('Skill Mapping'!$B$2:$B$7,MATCH(TRIM($J6),'Skill Mapping'!$A$2:$A$7,0)))) | L6: =IF($H6="","",'Survey Response'!$L4) | M6: =IF($L6="","",IF(COUNTIF('Skill Mapping'!$A$2:$A$7,TRIM($L6))=0,"",INDEX('Skill Mapping'!$B$2:$B$7,MATCH(TRIM($L6),'Skill Mapping'!$A$2:$A$7,0)))) | N6: =IF($H6="","",'Survey Response'!$M4) | O6: =IF($H6="","",IF('Survey Response'!$M4="Manager","R2","R1")) | P6: =IF($K6="","No",IF(COUNTIFS(MasterPanel!$B:$B,$H6,MasterPanel!$I:$I,$K6,MasterPanel!$K:$K,"Y")>0,"Yes","No")) -> No | Q6: =IF($K6="",0,IF(COUNTIF('Gap Sheet'!$A$6:$A$11,TRIM($J6))=0,0,IF($O6="R1",INDEX('Gap Sheet'!$C$6:$C$11,MATCH(TRIM($J6),'Gap Sheet'!$A$6:$A$11,0)),INDEX('Gap Sheet'!$G$6:$G$11,MATCH(TRIM($J6),'Gap Sheet'!$A$6:$A$11,0))))) -> 0 | R6: =IF($K6="","",$K6&"|"&$O6) | S6: =IF($R6="",0,COUNTIF($AA$4:$AA5,$R6)) -> 0 | T6: =IF(OR($I6<>"Yes, I'm available for in-person interviews at Chennai",$E6<>"Yes",$P6<>"Yes"),"No",IF(($Q6-$S6)>0,"Yes","No")) -> No | U6: =IF($M6="","No",IF(COUNTIFS(MasterPanel!$B:$B,$H6,MasterPanel!$I:$I,$M6,MasterPanel!$K:$K,"Y")>0,"Yes","No")) -> No | V6: =IF($M6="",0,IF(COUNTIF('Gap Sheet'!$A$6:$A$11,TRIM($L6))=0,0,IF($O6="R1",INDEX('Gap Sheet'!$C$6:$C$11,MATCH(TRIM($L6),'Gap Sheet'!$A$6:$A$11,0)),INDEX('Gap Sheet'!$G$6:$G$11,MATCH(TRIM($L6),'Gap Sheet'!$A$6:$A$11,0))))) -> 0 | W6: =IF($M6="","",$M6&"|"&$O6) | X6: =IF($W6="",0,COUNTIF($AA$4:$AA5,$W6)) -> 0 | Y6: =IF(OR($I6<>"Yes, I'm available for in-person interviews at Chennai",$E6<>"Yes",$T6="Yes",$U6<>"Yes"),"No",IF(($V6-$X6)>0,"Yes","No")) -> No | Z6: =IF($T6="Yes","Primary",IF($Y6="Yes","Secondary","")) | AA6: =IF($Z6="Primary",$R6,IF($Z6="Secondary",$W6,"")) | AB6: =IF($Z6="Primary","Matched on primary skill",IF($Z6="Secondary","Matched on secondary skill (primary not approved or not required)","")) | AC6: =IF($D6="Panel Details",$F6,"") | AD6: =IF($D6="Panel Details",'Survey Response'!$D4,"") | AE6: =IF($D6="Panel Details",'Survey Response'!$E4,"") | AF6: =IF($D6="Panel Details",'Survey Response'!$G4,"") | AG6: =IF($D6="Panel Details",IF($Z6="Primary",$J6,$L6),"") | AH6: =IF($D6="Panel Details",IF($Z6="Primary",$L6,$J6),"") | AI6: =IF($D6="Panel Details",'Survey Response'!$H4,"") | AJ6: =IF($D6="Panel Details",'Survey Response'!$M4,"") | AK6: =IF($D6="Panel Details",$O6,"") | AL6: =IF($D6="Panel Details",8,"") | AM6: =IF($D6="Panel Details",$AB6,"") | AN6: =IF($D6="Panel Details","Yes","") | AP6: =IF($D6="Followup",'Survey Response'!$D4,"") | AQ6: =IF($D6="Followup",'Survey Response'!$E4,"") | AR6: =IF($D6="Followup",'Survey Response'!$G4,"") | AS6: =IF($D6="Followup",'Survey Response'!$H4,"") | AT6: =IF($D6="Followup",'Survey Response'!$M4,"") | AU6: =IF($D6="Followup",'Survey Response'!$K4,"") | AV6: =IF($D6="Followup",'Survey Response'!$L4,"") | AW6: =IF($D6="Followup",IF(AND($P6<>"Yes",$U6<>"Yes"),"Not approved for primary or secondary skill","Approved, but skill(s) no longer have capacity (fully staffed)"),"")
A7: =IF('Survey Response'!$D5="","",'Survey Response'!$A5&"|"&LOWER(TRIM('Survey Response'!$D5))) | B7: =IF($H7="","",$F7&"|"&$H7) | C7: =IF($H7="","",$A7=$B7) | D7: =IF($H7="","",IF($E7<>"Yes","Superseded",IF($I7<>"Yes, I'm available for in-person interviews at Chennai","Not Available",IF($Z7<>"","Panel Details","Followup")))) | E7: =IF($H7="","",IF(SUMPRODUCT(($H$4:$H$503=$H7)*(($G$4:$G$503>$G7)+($G$4:$G$503=$G7)*($F$4:$F$503>$F7)))=0,"Yes","No")) | F7: =IF('Survey Response'!$D5="","",INT('Survey Response'!$A5)) | G7: =IF('Survey Response'!$D5="","",'Survey Response'!$C5) | H7: =IF('Survey Response'!$D5="","",LOWER(TRIM('Survey Response'!$D5))) | I7: =IF($H7="","",'Survey Response'!$I5) | J7: =IF($H7="","",'Survey Response'!$K5) | K7: =IF($J7="","",IF(COUNTIF('Skill Mapping'!$A$2:$A$7,TRIM($J7))=0,"",INDEX('Skill Mapping'!$B$2:$B$7,MATCH(TRIM($J7),'Skill Mapping'!$A$2:$A$7,0)))) | L7: =IF($H7="","",'Survey Response'!$L5) | M7: =IF($L7="","",IF(COUNTIF('Skill Mapping'!$A$2:$A$7,TRIM($L7))=0,"",INDEX('Skill Mapping'!$B$2:$B$7,MATCH(TRIM($L7),'Skill Mapping'!$A$2:$A$7,0)))) | N7: =IF($H7="","",'Survey Response'!$M5) | O7: =IF($H7="","",IF('Survey Response'!$M5="Manager","R2","R1")) | P7: =IF($K7="","No",IF(COUNTIFS(MasterPanel!$B:$B,$H7,MasterPanel!$I:$I,$K7,MasterPanel!$K:$K,"Y")>0,"Yes","No")) -> No | Q7: =IF($K7="",0,IF(COUNTIF('Gap Sheet'!$A$6:$A$11,TRIM($J7))=0,0,IF($O7="R1",INDEX('Gap Sheet'!$C$6:$C$11,MATCH(TRIM($J7),'Gap Sheet'!$A$6:$A$11,0)),INDEX('Gap Sheet'!$G$6:$G$11,MATCH(TRIM($J7),'Gap Sheet'!$A$6:$A$11,0))))) -> 0 | R7: =IF($K7="","",$K7&"|"&$O7) | S7: =IF($R7="",0,COUNTIF($AA$4:$AA6,$R7)) -> 0 | T7: =IF(OR($I7<>"Yes, I'm available for in-person interviews at Chennai",$E7<>"Yes",$P7<>"Yes"),"No",IF(($Q7-$S7)>0,"Yes","No")) -> No | U7: =IF($M7="","No",IF(COUNTIFS(MasterPanel!$B:$B,$H7,MasterPanel!$I:$I,$M7,MasterPanel!$K:$K,"Y")>0,"Yes","No")) -> No | V7: =IF($M7="",0,IF(COUNTIF('Gap Sheet'!$A$6:$A$11,TRIM($L7))=0,0,IF($O7="R1",INDEX('Gap Sheet'!$C$6:$C$11,MATCH(TRIM($L7),'Gap Sheet'!$A$6:$A$11,0)),INDEX('Gap Sheet'!$G$6:$G$11,MATCH(TRIM($L7),'Gap Sheet'!$A$6:$A$11,0))))) -> 0 | W7: =IF($M7="","",$M7&"|"&$O7) | X7: =IF($W7="",0,COUNTIF($AA$4:$AA6,$W7)) -> 0 | Y7: =IF(OR($I7<>"Yes, I'm available for in-person interviews at Chennai",$E7<>"Yes",$T7="Yes",$U7<>"Yes"),"No",IF(($V7-$X7)>0,"Yes","No")) -> No | Z7: =IF($T7="Yes","Primary",IF($Y7="Yes","Secondary","")) | AA7: =IF($Z7="Primary",$R7,IF($Z7="Secondary",$W7,"")) | AB7: =IF($Z7="Primary","Matched on primary skill",IF($Z7="Secondary","Matched on secondary skill (primary not approved or not required)","")) | AC7: =IF($D7="Panel Details",$F7,"") | AD7: =IF($D7="Panel Details",'Survey Response'!$D5,"") | AE7: =IF($D7="Panel Details",'Survey Response'!$E5,"") | AF7: =IF($D7="Panel Details",'Survey Response'!$G5,"") | AG7: =IF($D7="Panel Details",IF($Z7="Primary",$J7,$L7),"") | AH7: =IF($D7="Panel Details",IF($Z7="Primary",$L7,$J7),"") | AI7: =IF($D7="Panel Details",'Survey Response'!$H5,"") | AJ7: =IF($D7="Panel Details",'Survey Response'!$M5,"") | AK7: =IF($D7="Panel Details",$O7,"") | AL7: =IF($D7="Panel Details",8,"") | AM7: =IF($D7="Panel Details",$AB7,"") | AN7: =IF($D7="Panel Details","Yes","") | AP7: =IF($D7="Followup",'Survey Response'!$D5,"") | AQ7: =IF($D7="Followup",'Survey Response'!$E5,"") | AR7: =IF($D7="Followup",'Survey Response'!$G5,"") | AS7: =IF($D7="Followup",'Survey Response'!$H5,"") | AT7: =IF($D7="Followup",'Survey Response'!$M5,"") | AU7: =IF($D7="Followup",'Survey Response'!$K5,"") | AV7: =IF($D7="Followup",'Survey Response'!$L5,"") | AW7: =IF($D7="Followup",IF(AND($P7<>"Yes",$U7<>"Yes"),"Not approved for primary or secondary skill","Approved, but skill(s) no longer have capacity (fully staffed)"),"")
A8: =IF('Survey Response'!$D6="","",'Survey Response'!$A6&"|"&LOWER(TRIM('Survey Response'!$D6))) | B8: =IF($H8="","",$F8&"|"&$H8) | C8: =IF($H8="","",$A8=$B8) | D8: =IF($H8="","",IF($E8<>"Yes","Superseded",IF($I8<>"Yes, I'm available for in-person interviews at Chennai","Not Available",IF($Z8<>"","Panel Details","Followup")))) | E8: =IF($H8="","",IF(SUMPRODUCT(($H$4:$H$503=$H8)*(($G$4:$G$503>$G8)+($G$4:$G$503=$G8)*($F$4:$F$503>$F8)))=0,"Yes","No")) | F8: =IF('Survey Response'!$D6="","",INT('Survey Response'!$A6)) | G8: =IF('Survey Response'!$D6="","",'Survey Response'!$C6) | H8: =IF('Survey Response'!$D6="","",LOWER(TRIM('Survey Response'!$D6))) | I8: =IF($H8="","",'Survey Response'!$I6) | J8: =IF($H8="","",'Survey Response'!$K6) | K8: =IF($J8="","",IF(COUNTIF('Skill Mapping'!$A$2:$A$7,TRIM($J8))=0,"",INDEX('Skill Mapping'!$B$2:$B$7,MATCH(TRIM($J8),'Skill Mapping'!$A$2:$A$7,0)))) | L8: =IF($H8="","",'Survey Response'!$L6) | M8: =IF($L8="","",IF(COUNTIF('Skill Mapping'!$A$2:$A$7,TRIM($L8))=0,"",INDEX('Skill Mapping'!$B$2:$B$7,MATCH(TRIM($L8),'Skill Mapping'!$A$2:$A$7,0)))) | N8: =IF($H8="","",'Survey Response'!$M6) | O8: =IF($H8="","",IF('Survey Response'!$M6="Manager","R2","R1")) | P8: =IF($K8="","No",IF(COUNTIFS(MasterPanel!$B:$B,$H8,MasterPanel!$I:$I,$K8,MasterPanel!$K:$K,"Y")>0,"Yes","No")) -> No | Q8: =IF($K8="",0,IF(COUNTIF('Gap Sheet'!$A$6:$A$11,TRIM($J8))=0,0,IF($O8="R1",INDEX('Gap Sheet'!$C$6:$C$11,MATCH(TRIM($J8),'Gap Sheet'!$A$6:$A$11,0)),INDEX('Gap Sheet'!$G$6:$G$11,MATCH(TRIM($J8),'Gap Sheet'!$A$6:$A$11,0))))) -> 0 | R8: =IF($K8="","",$K8&"|"&$O8) | S8: =IF($R8="",0,COUNTIF($AA$4:$AA7,$R8)) -> 0 | T8: =IF(OR($I8<>"Yes, I'm available for in-person interviews at Chennai",$E8<>"Yes",$P8<>"Yes"),"No",IF(($Q8-$S8)>0,"Yes","No")) -> No | U8: =IF($M8="","No",IF(COUNTIFS(MasterPanel!$B:$B,$H8,MasterPanel!$I:$I,$M8,MasterPanel!$K:$K,"Y")>0,"Yes","No")) -> No | V8: =IF($M8="",0,IF(COUNTIF('Gap Sheet'!$A$6:$A$11,TRIM($L8))=0,0,IF($O8="R1",INDEX('Gap Sheet'!$C$6:$C$11,MATCH(TRIM($L8),'Gap Sheet'!$A$6:$A$11,0)),INDEX('Gap Sheet'!$G$6:$G$11,MATCH(TRIM($L8),'Gap Sheet'!$A$6:$A$11,0))))) -> 0 | W8: =IF($M8="","",$M8&"|"&$O8) | X8: =IF($W8="",0,COUNTIF($AA$4:$AA7,$W8)) -> 0 | Y8: =IF(OR($I8<>"Yes, I'm available for in-person interviews at Chennai",$E8<>"Yes",$T8="Yes",$U8<>"Yes"),"No",IF(($V8-$X8)>0,"Yes","No")) -> No | Z8: =IF($T8="Yes","Primary",IF($Y8="Yes","Secondary","")) | AA8: =IF($Z8="Primary",$R8,IF($Z8="Secondary",$W8,"")) | AB8: =IF($Z8="Primary","Matched on primary skill",IF($Z8="Secondary","Matched on secondary skill (primary not approved or not required)","")) | AC8: =IF($D8="Panel Details",$F8,"") | AD8: =IF($D8="Panel Details",'Survey Response'!$D6,"") | AE8: =IF($D8="Panel Details",'Survey Response'!$E6,"") | AF8: =IF($D8="Panel Details",'Survey Response'!$G6,"") | AG8: =IF($D8="Panel Details",IF($Z8="Primary",$J8,$L8),"") | AH8: =IF($D8="Panel Details",IF($Z8="Primary",$L8,$J8),"") | AI8: =IF($D8="Panel Details",'Survey Response'!$H6,"") | AJ8: =IF($D8="Panel Details",'Survey Response'!$M6,"") | AK8: =IF($D8="Panel Details",$O8,"") | AL8: =IF($D8="Panel Details",8,"") | AM8: =IF($D8="Panel Details",$AB8,"") | AN8: =IF($D8="Panel Details","Yes","") | AP8: =IF($D8="Followup",'Survey Response'!$D6,"") | AQ8: =IF($D8="Followup",'Survey Response'!$E6,"") | AR8: =IF($D8="Followup",'Survey Response'!$G6,"") | AS8: =IF($D8="Followup",'Survey Response'!$H6,"") | AT8: =IF($D8="Followup",'Survey Response'!$M6,"") | AU8: =IF($D8="Followup",'Survey Response'!$K6,"") | AV8: =IF($D8="Followup",'Survey Response'!$L6,"") | AW8: =IF($D8="Followup",IF(AND($P8<>"Yes",$U8<>"Yes"),"Not approved for primary or secondary skill","Approved, but skill(s) no longer have capacity (fully staffed)"),"")
A9: =IF('Survey Response'!$D7="","",'Survey Response'!$A7&"|"&LOWER(TRIM('Survey Response'!$D7))) | B9: =IF($H9="","",$F9&"|"&$H9) | C9: =IF($H9="","",$A9=$B9) | D9: =IF($H9="","",IF($E9<>"Yes","Superseded",IF($I9<>"Yes, I'm available for in-person interviews at Chennai","Not Available",IF($Z9<>"","Panel Details","Followup")))) | E9: =IF($H9="","",IF(SUMPRODUCT(($H$4:$H$503=$H9)*(($G$4:$G$503>$G9)+($G$4:$G$503=$G9)*($F$4:$F$503>$F9)))=0,"Yes","No")) | F9: =IF('Survey Response'!$D7="","",INT('Survey Response'!$A7)) | G9: =IF('Survey Response'!$D7="","",'Survey Response'!$C7) | H9: =IF('Survey Response'!$D7="","",LOWER(TRIM('Survey Response'!$D7))) | I9: =IF($H9="","",'Survey Response'!$I7) | J9: =IF($H9="","",'Survey Response'!$K7) | K9: =IF($J9="","",IF(COUNTIF('Skill Mapping'!$A$2:$A$7,TRIM($J9))=0,"",INDEX('Skill Mapping'!$B$2:$B$7,MATCH(TRIM($J9),'Skill Mapping'!$A$2:$A$7,0)))) | L9: =IF($H9="","",'Survey Response'!$L7) | M9: =IF($L9="","",IF(COUNTIF('Skill Mapping'!$A$2:$A$7,TRIM($L9))=0,"",INDEX('Skill Mapping'!$B$2:$B$7,MATCH(TRIM($L9),'Skill Mapping'!$A$2:$A$7,0)))) | N9: =IF($H9="","",'Survey Response'!$M7) | O9: =IF($H9="","",IF('Survey Response'!$M7="Manager","R2","R1")) | P9: =IF($K9="","No",IF(COUNTIFS(MasterPanel!$B:$B,$H9,MasterPanel!$I:$I,$K9,MasterPanel!$K:$K,"Y")>0,"Yes","No")) -> No | Q9: =IF($K9="",0,IF(COUNTIF('Gap Sheet'!$A$6:$A$11,TRIM($J9))=0,0,IF($O9="R1",INDEX('Gap Sheet'!$C$6:$C$11,MATCH(TRIM($J9),'Gap Sheet'!$A$6:$A$11,0)),INDEX('Gap Sheet'!$G$6:$G$11,MATCH(TRIM($J9),'Gap Sheet'!$A$6:$A$11,0))))) -> 0 | R9: =IF($K9="","",$K9&"|"&$O9) | S9: =IF($R9="",0,COUNTIF($AA$4:$AA8,$R9)) -> 0 | T9: =IF(OR($I9<>"Yes, I'm available for in-person interviews at Chennai",$E9<>"Yes",$P9<>"Yes"),"No",IF(($Q9-$S9)>0,"Yes","No")) -> No | U9: =IF($M9="","No",IF(COUNTIFS(MasterPanel!$B:$B,$H9,MasterPanel!$I:$I,$M9,MasterPanel!$K:$K,"Y")>0,"Yes","No")) -> No | V9: =IF($M9="",0,IF(COUNTIF('Gap Sheet'!$A$6:$A$11,TRIM($L9))=0,0,IF($O9="R1",INDEX('Gap Sheet'!$C$6:$C$11,MATCH(TRIM($L9),'Gap Sheet'!$A$6:$A$11,0)),INDEX('Gap Sheet'!$G$6:$G$11,MATCH(TRIM($L9),'Gap Sheet'!$A$6:$A$11,0))))) -> 0 | W9: =IF($M9="","",$M9&"|"&$O9) | X9: =IF($W9="",0,COUNTIF($AA$4:$AA8,$W9)) -> 0 | Y9: =IF(OR($I9<>"Yes, I'm available for in-person interviews at Chennai",$E9<>"Yes",$T9="Yes",$U9<>"Yes"),"No",IF(($V9-$X9)>0,"Yes","No")) -> No | Z9: =IF($T9="Yes","Primary",IF($Y9="Yes","Secondary","")) | AA9: =IF($Z9="Primary",$R9,IF($Z9="Secondary",$W9,"")) | AB9: =IF($Z9="Primary","Matched on primary skill",IF($Z9="Secondary","Matched on secondary skill (primary not approved or not required)","")) | AC9: =IF($D9="Panel Details",$F9,"") | AD9: =IF($D9="Panel Details",'Survey Response'!$D7,"") | AE9: =IF($D9="Panel Details",'Survey Response'!$E7,"") | AF9: =IF($D9="Panel Details",'Survey Response'!$G7,"") | AG9: =IF($D9="Panel Details",IF($Z9="Primary",$J9,$L9),"") | AH9: =IF($D9="Panel Details",IF($Z9="Primary",$L9,$J9),"") | AI9: =IF($D9="Panel Details",'Survey Response'!$H7,"") | AJ9: =IF($D9="Panel Details",'Survey Response'!$M7,"") | AK9: =IF($D9="Panel Details",$O9,"") | AL9: =IF($D9="Panel Details",8,"") | AM9: =IF($D9="Panel Details",$AB9,"") | AN9: =IF($D9="Panel Details","Yes","") | AP9: =IF($D9="Followup",'Survey Response'!$D7,"") | AQ9: =IF($D9="Followup",'Survey Response'!$E7,"") | AR9: =IF($D9="Followup",'Survey Response'!$G7,"") | AS9: =IF($D9="Followup",'Survey Response'!$H7,"") | AT9: =IF($D9="Followup",'Survey Response'!$M7,"") | AU9: =IF($D9="Followup",'Survey Response'!$K7,"") | AV9: =IF($D9="Followup",'Survey Response'!$L7,"") | AW9: =IF($D9="Followup",IF(AND($P9<>"Yes",$U9<>"Yes"),"Not approved for primary or secondary skill","Approved, but skill(s) no longer have capacity (fully staffed)"),"")
